[2022-07-22 14:38:14,414] {taskinstance.py:1032} INFO - Dependencies all met for <TaskInstance: data_ingestion_dag.download_dataset2.csv_task scheduled__2022-07-22T00:00:00+00:00 [queued]>
[2022-07-22 14:38:14,433] {taskinstance.py:1032} INFO - Dependencies all met for <TaskInstance: data_ingestion_dag.download_dataset2.csv_task scheduled__2022-07-22T00:00:00+00:00 [queued]>
[2022-07-22 14:38:14,434] {taskinstance.py:1238} INFO - 
--------------------------------------------------------------------------------
[2022-07-22 14:38:14,434] {taskinstance.py:1239} INFO - Starting attempt 1 of 1
[2022-07-22 14:38:14,434] {taskinstance.py:1240} INFO - 
--------------------------------------------------------------------------------
[2022-07-22 14:38:14,457] {taskinstance.py:1259} INFO - Executing <Task(BashOperator): download_dataset2.csv_task> on 2022-07-22 00:00:00+00:00
[2022-07-22 14:38:14,464] {standard_task_runner.py:52} INFO - Started process 3915 to run task
[2022-07-22 14:38:14,475] {standard_task_runner.py:76} INFO - Running: ['***', 'tasks', 'run', 'data_ingestion_dag', 'download_dataset2.csv_task', 'scheduled__2022-07-22T00:00:00+00:00', '--job-id', '3', '--raw', '--subdir', 'DAGS_FOLDER/data_ingestion_dag.py', '--cfg-path', '/tmp/tmp6ul6w3g3', '--error-file', '/tmp/tmp1g5ifs80']
[2022-07-22 14:38:14,477] {standard_task_runner.py:77} INFO - Job 3: Subtask download_dataset2.csv_task
[2022-07-22 14:38:14,577] {logging_mixin.py:109} INFO - Running <TaskInstance: data_ingestion_dag.download_dataset2.csv_task scheduled__2022-07-22T00:00:00+00:00 [running]> on host b53e6dc6abdf
[2022-07-22 14:38:14,698] {taskinstance.py:1426} INFO - Exporting the following env vars:
AIRFLOW_CTX_DAG_OWNER=***
AIRFLOW_CTX_DAG_ID=data_ingestion_dag
AIRFLOW_CTX_TASK_ID=download_dataset2.csv_task
AIRFLOW_CTX_EXECUTION_DATE=2022-07-22T00:00:00+00:00
AIRFLOW_CTX_DAG_RUN_ID=scheduled__2022-07-22T00:00:00+00:00
[2022-07-22 14:38:14,701] {subprocess.py:62} INFO - Tmp dir root location: 
 /tmp
[2022-07-22 14:38:14,702] {subprocess.py:74} INFO - Running command: ['bash', '-c', 'curl -sS dataset_url/dataset2.csv > /opt/***/data/raw/dataset2.csv']
[2022-07-22 14:38:14,719] {subprocess.py:85} INFO - Output:
[2022-07-22 14:38:14,725] {subprocess.py:89} INFO - bash: /opt/***/data/raw/dataset2.csv: No such file or directory
[2022-07-22 14:38:14,729] {subprocess.py:93} INFO - Command exited with return code 1
[2022-07-22 14:38:14,784] {taskinstance.py:1700} ERROR - Task failed with exception
Traceback (most recent call last):
  File "/home/airflow/.local/lib/python3.7/site-packages/airflow/models/taskinstance.py", line 1329, in _run_raw_task
    self._execute_task_with_callbacks(context)
  File "/home/airflow/.local/lib/python3.7/site-packages/airflow/models/taskinstance.py", line 1455, in _execute_task_with_callbacks
    result = self._execute_task(context, self.task)
  File "/home/airflow/.local/lib/python3.7/site-packages/airflow/models/taskinstance.py", line 1511, in _execute_task
    result = execute_callable(context=context)
  File "/home/airflow/.local/lib/python3.7/site-packages/airflow/operators/bash.py", line 188, in execute
    f'Bash command failed. The command returned a non-zero exit code {result.exit_code}.'
airflow.exceptions.AirflowException: Bash command failed. The command returned a non-zero exit code 1.
[2022-07-22 14:38:14,805] {taskinstance.py:1277} INFO - Marking task as FAILED. dag_id=data_ingestion_dag, task_id=download_dataset2.csv_task, execution_date=20220722T000000, start_date=20220722T143814, end_date=20220722T143814
[2022-07-22 14:38:14,861] {standard_task_runner.py:92} ERROR - Failed to execute job 3 for task download_dataset2.csv_task
Traceback (most recent call last):
  File "/home/airflow/.local/lib/python3.7/site-packages/airflow/task/task_runner/standard_task_runner.py", line 85, in _start_by_fork
    args.func(args, dag=self.dag)
  File "/home/airflow/.local/lib/python3.7/site-packages/airflow/cli/cli_parser.py", line 48, in command
    return func(*args, **kwargs)
  File "/home/airflow/.local/lib/python3.7/site-packages/airflow/utils/cli.py", line 92, in wrapper
    return f(*args, **kwargs)
  File "/home/airflow/.local/lib/python3.7/site-packages/airflow/cli/commands/task_command.py", line 298, in task_run
    _run_task_by_selected_method(args, dag, ti)
  File "/home/airflow/.local/lib/python3.7/site-packages/airflow/cli/commands/task_command.py", line 107, in _run_task_by_selected_method
    _run_raw_task(args, ti)
  File "/home/airflow/.local/lib/python3.7/site-packages/airflow/cli/commands/task_command.py", line 184, in _run_raw_task
    error_file=args.error_file,
  File "/home/airflow/.local/lib/python3.7/site-packages/airflow/utils/session.py", line 70, in wrapper
    return func(*args, session=session, **kwargs)
  File "/home/airflow/.local/lib/python3.7/site-packages/airflow/models/taskinstance.py", line 1329, in _run_raw_task
    self._execute_task_with_callbacks(context)
  File "/home/airflow/.local/lib/python3.7/site-packages/airflow/models/taskinstance.py", line 1455, in _execute_task_with_callbacks
    result = self._execute_task(context, self.task)
  File "/home/airflow/.local/lib/python3.7/site-packages/airflow/models/taskinstance.py", line 1511, in _execute_task
    result = execute_callable(context=context)
  File "/home/airflow/.local/lib/python3.7/site-packages/airflow/operators/bash.py", line 188, in execute
    f'Bash command failed. The command returned a non-zero exit code {result.exit_code}.'
airflow.exceptions.AirflowException: Bash command failed. The command returned a non-zero exit code 1.
[2022-07-22 14:38:14,918] {local_task_job.py:154} INFO - Task exited with return code 1
[2022-07-22 14:38:15,000] {local_task_job.py:264} INFO - 0 downstream tasks scheduled from follow-on schedule check
