[2022-07-22 14:40:20,303] {taskinstance.py:1032} INFO - Dependencies all met for <TaskInstance: data_ingestion_dag.download_dataset1.csv_task scheduled__2022-07-22T00:00:00+00:00 [queued]>
[2022-07-22 14:40:20,329] {taskinstance.py:1032} INFO - Dependencies all met for <TaskInstance: data_ingestion_dag.download_dataset1.csv_task scheduled__2022-07-22T00:00:00+00:00 [queued]>
[2022-07-22 14:40:20,329] {taskinstance.py:1238} INFO - 
--------------------------------------------------------------------------------
[2022-07-22 14:40:20,330] {taskinstance.py:1239} INFO - Starting attempt 2 of 2
[2022-07-22 14:40:20,330] {taskinstance.py:1240} INFO - 
--------------------------------------------------------------------------------
[2022-07-22 14:40:20,358] {taskinstance.py:1259} INFO - Executing <Task(BashOperator): download_dataset1.csv_task> on 2022-07-22 00:00:00+00:00
[2022-07-22 14:40:20,365] {standard_task_runner.py:52} INFO - Started process 4092 to run task
[2022-07-22 14:40:20,376] {standard_task_runner.py:76} INFO - Running: ['***', 'tasks', 'run', 'data_ingestion_dag', 'download_dataset1.csv_task', 'scheduled__2022-07-22T00:00:00+00:00', '--job-id', '6', '--raw', '--subdir', 'DAGS_FOLDER/data_ingestion_dag.py', '--cfg-path', '/tmp/tmpj7rj68an', '--error-file', '/tmp/tmphbjz0iep']
[2022-07-22 14:40:20,377] {standard_task_runner.py:77} INFO - Job 6: Subtask download_dataset1.csv_task
[2022-07-22 14:40:20,488] {logging_mixin.py:109} INFO - Running <TaskInstance: data_ingestion_dag.download_dataset1.csv_task scheduled__2022-07-22T00:00:00+00:00 [running]> on host b53e6dc6abdf
[2022-07-22 14:40:20,614] {taskinstance.py:1426} INFO - Exporting the following env vars:
AIRFLOW_CTX_DAG_OWNER=***
AIRFLOW_CTX_DAG_ID=data_ingestion_dag
AIRFLOW_CTX_TASK_ID=download_dataset1.csv_task
AIRFLOW_CTX_EXECUTION_DATE=2022-07-22T00:00:00+00:00
AIRFLOW_CTX_DAG_RUN_ID=scheduled__2022-07-22T00:00:00+00:00
[2022-07-22 14:40:20,616] {subprocess.py:62} INFO - Tmp dir root location: 
 /tmp
[2022-07-22 14:40:20,617] {subprocess.py:74} INFO - Running command: ['bash', '-c', 'curl -sS https://raw.githubusercontent.com/ameeraadam/Data-Engineer-Tech-Challenge/main//dataset1.csv > /opt/***/data/raw/dataset1.csv']
[2022-07-22 14:40:20,633] {subprocess.py:85} INFO - Output:
[2022-07-22 14:40:20,638] {subprocess.py:89} INFO - bash: /opt/***/data/raw/dataset1.csv: No such file or directory
[2022-07-22 14:40:20,639] {subprocess.py:93} INFO - Command exited with return code 1
[2022-07-22 14:40:20,665] {taskinstance.py:1700} ERROR - Task failed with exception
Traceback (most recent call last):
  File "/home/airflow/.local/lib/python3.7/site-packages/airflow/models/taskinstance.py", line 1329, in _run_raw_task
    self._execute_task_with_callbacks(context)
  File "/home/airflow/.local/lib/python3.7/site-packages/airflow/models/taskinstance.py", line 1455, in _execute_task_with_callbacks
    result = self._execute_task(context, self.task)
  File "/home/airflow/.local/lib/python3.7/site-packages/airflow/models/taskinstance.py", line 1511, in _execute_task
    result = execute_callable(context=context)
  File "/home/airflow/.local/lib/python3.7/site-packages/airflow/operators/bash.py", line 188, in execute
    f'Bash command failed. The command returned a non-zero exit code {result.exit_code}.'
airflow.exceptions.AirflowException: Bash command failed. The command returned a non-zero exit code 1.
[2022-07-22 14:40:20,679] {taskinstance.py:1277} INFO - Marking task as FAILED. dag_id=data_ingestion_dag, task_id=download_dataset1.csv_task, execution_date=20220722T000000, start_date=20220722T144020, end_date=20220722T144020
[2022-07-22 14:40:20,709] {standard_task_runner.py:92} ERROR - Failed to execute job 6 for task download_dataset1.csv_task
Traceback (most recent call last):
  File "/home/airflow/.local/lib/python3.7/site-packages/airflow/task/task_runner/standard_task_runner.py", line 85, in _start_by_fork
    args.func(args, dag=self.dag)
  File "/home/airflow/.local/lib/python3.7/site-packages/airflow/cli/cli_parser.py", line 48, in command
    return func(*args, **kwargs)
  File "/home/airflow/.local/lib/python3.7/site-packages/airflow/utils/cli.py", line 92, in wrapper
    return f(*args, **kwargs)
  File "/home/airflow/.local/lib/python3.7/site-packages/airflow/cli/commands/task_command.py", line 298, in task_run
    _run_task_by_selected_method(args, dag, ti)
  File "/home/airflow/.local/lib/python3.7/site-packages/airflow/cli/commands/task_command.py", line 107, in _run_task_by_selected_method
    _run_raw_task(args, ti)
  File "/home/airflow/.local/lib/python3.7/site-packages/airflow/cli/commands/task_command.py", line 184, in _run_raw_task
    error_file=args.error_file,
  File "/home/airflow/.local/lib/python3.7/site-packages/airflow/utils/session.py", line 70, in wrapper
    return func(*args, session=session, **kwargs)
  File "/home/airflow/.local/lib/python3.7/site-packages/airflow/models/taskinstance.py", line 1329, in _run_raw_task
    self._execute_task_with_callbacks(context)
  File "/home/airflow/.local/lib/python3.7/site-packages/airflow/models/taskinstance.py", line 1455, in _execute_task_with_callbacks
    result = self._execute_task(context, self.task)
  File "/home/airflow/.local/lib/python3.7/site-packages/airflow/models/taskinstance.py", line 1511, in _execute_task
    result = execute_callable(context=context)
  File "/home/airflow/.local/lib/python3.7/site-packages/airflow/operators/bash.py", line 188, in execute
    f'Bash command failed. The command returned a non-zero exit code {result.exit_code}.'
airflow.exceptions.AirflowException: Bash command failed. The command returned a non-zero exit code 1.
[2022-07-22 14:40:20,755] {local_task_job.py:154} INFO - Task exited with return code 1
[2022-07-22 14:40:20,834] {local_task_job.py:264} INFO - 0 downstream tasks scheduled from follow-on schedule check
